version: "3.7"

services:
  deluge:
    image: linuxserver/deluge:latest
    networks:
      - overlay_network
    ports:
      - ${HTPC_DELUGE_DOWNLOAD_PORT}:12345
    environment:
      - PUID=${PUID}
      - PGID=${GROUP_ID_DOWNLOADERS}
      - TZ=${TZ}
      - UMASK=007
      - DELUGE_LOGLEVEL=error
    volumes:
      - "${HTPC_CONFIG_DIR}/deluge:/config"
      - "${HTPC_DOWNLOAD_DIR}:/downloads"
      - ./deluge/WebAPI-0.4.0-py3.6.egg:/usr/lib/python3/dist-packages/deluge/plugins/WebAPI-0.4.0-py3.6.egg
    healthcheck:
      test: ["CMD", "curl", "-f", "http://localhost:8112"]
      interval: 2m
      timeout: 5s
      retries: 3
      start_period: 30s
    deploy:
      restart_policy:
        condition: on-failure
      labels:
        - traefik.enable=true
        - traefik.http.routers.deluge.entrypoints=websecure
        - traefik.http.routers.deluge.rule=Host(`deluge.${HTPC_DOMAIN}`)
        - traefik.http.routers.deluge.tls=true
        - traefik.http.routers.deluge.middlewares=auth
        - traefik.http.services.deluge.loadbalancer.server.port=8112

networks:
  overlay_network:
    external: true
